[2024-05-04T07:23:36.919+0000] {local_task_job_runner.py:120} INFO - ::group::Pre task execution logs
[2024-05-04T07:23:36.930+0000] {taskinstance.py:2073} INFO - Dependencies all met for dep_context=non-requeueable deps ti=<TaskInstance: weather_dag.transform_load_weather_data manual__2024-05-04T07:19:16.663447+00:00 [queued]>
[2024-05-04T07:23:36.939+0000] {taskinstance.py:2073} INFO - Dependencies all met for dep_context=requeueable deps ti=<TaskInstance: weather_dag.transform_load_weather_data manual__2024-05-04T07:19:16.663447+00:00 [queued]>
[2024-05-04T07:23:36.939+0000] {taskinstance.py:2303} INFO - Starting attempt 3 of 3
[2024-05-04T07:23:36.954+0000] {taskinstance.py:2327} INFO - Executing <Task(PythonOperator): transform_load_weather_data> on 2024-05-04 07:19:16.663447+00:00
[2024-05-04T07:23:36.961+0000] {standard_task_runner.py:63} INFO - Started process 26130 to run task
[2024-05-04T07:23:36.964+0000] {standard_task_runner.py:90} INFO - Running: ['airflow', 'tasks', 'run', 'weather_dag', 'transform_load_weather_data', 'manual__2024-05-04T07:19:16.663447+00:00', '--job-id', '36', '--raw', '--subdir', 'DAGS_FOLDER/weather_dag.py', '--cfg-path', '/tmp/tmpyf8nydb2']
[2024-05-04T07:23:36.965+0000] {standard_task_runner.py:91} INFO - Job 36: Subtask transform_load_weather_data
[2024-05-04T07:23:37.009+0000] {task_command.py:426} INFO - Running <TaskInstance: weather_dag.transform_load_weather_data manual__2024-05-04T07:19:16.663447+00:00 [running]> on host ip-172-31-26-226.eu-north-1.compute.internal
[2024-05-04T07:23:37.083+0000] {taskinstance.py:2644} INFO - Exporting env vars: AIRFLOW_CTX_DAG_EMAIL='myemail@domain.com' AIRFLOW_CTX_DAG_OWNER='airflow' AIRFLOW_CTX_DAG_ID='weather_dag' AIRFLOW_CTX_TASK_ID='transform_load_weather_data' AIRFLOW_CTX_EXECUTION_DATE='2024-05-04T07:19:16.663447+00:00' AIRFLOW_CTX_TRY_NUMBER='3' AIRFLOW_CTX_DAG_RUN_ID='manual__2024-05-04T07:19:16.663447+00:00'
[2024-05-04T07:23:37.085+0000] {taskinstance.py:430} INFO - ::endgroup::
[2024-05-04T07:23:37.578+0000] {taskinstance.py:441} INFO - ::group::Post task execution logs
[2024-05-04T07:23:37.579+0000] {taskinstance.py:2890} ERROR - Task failed with exception
Traceback (most recent call last):
  File "/home/ubuntu/airflow_environment/lib/python3.12/site-packages/s3fs/core.py", line 113, in _error_wrapper
    return await func(*args, **kwargs)
           ^^^^^^^^^^^^^^^^^^^^^^^^^^^
  File "/home/ubuntu/airflow_environment/lib/python3.12/site-packages/aiobotocore/client.py", line 408, in _make_api_call
    raise error_class(parsed_response, operation_name)
botocore.exceptions.ClientError: An error occurred (InvalidToken) when calling the CreateBucket operation: The provided token is malformed or otherwise invalid.

The above exception was the direct cause of the following exception:

Traceback (most recent call last):
  File "/home/ubuntu/airflow_environment/lib/python3.12/site-packages/airflow/models/taskinstance.py", line 465, in _execute_task
    result = _execute_callable(context=context, **execute_callable_kwargs)
             ^^^^^^^^^^^^^^^^^^^^^^^^^^^^^^^^^^^^^^^^^^^^^^^^^^^^^^^^^^^^^
  File "/home/ubuntu/airflow_environment/lib/python3.12/site-packages/airflow/models/taskinstance.py", line 432, in _execute_callable
    return execute_callable(context=context, **execute_callable_kwargs)
           ^^^^^^^^^^^^^^^^^^^^^^^^^^^^^^^^^^^^^^^^^^^^^^^^^^^^^^^^^^^^
  File "/home/ubuntu/airflow_environment/lib/python3.12/site-packages/airflow/models/baseoperator.py", line 400, in wrapper
    return func(self, *args, **kwargs)
           ^^^^^^^^^^^^^^^^^^^^^^^^^^^
  File "/home/ubuntu/airflow_environment/lib/python3.12/site-packages/airflow/operators/python.py", line 235, in execute
    return_value = self.execute_callable()
                   ^^^^^^^^^^^^^^^^^^^^^^^
  File "/home/ubuntu/airflow_environment/lib/python3.12/site-packages/airflow/operators/python.py", line 252, in execute_callable
    return self.python_callable(*self.op_args, **self.op_kwargs)
           ^^^^^^^^^^^^^^^^^^^^^^^^^^^^^^^^^^^^^^^^^^^^^^^^^^^^^
  File "/home/ubuntu/airflow/dags/weather_dag.py", line 68, in transform_load_data
    df_data.to_csv(f"s3://mybreakdata/{dt_string}.csv", index=False, storage_options=aws_credentials)
  File "/home/ubuntu/airflow_environment/lib/python3.12/site-packages/pandas/util/_decorators.py", line 333, in wrapper
    return func(*args, **kwargs)
           ^^^^^^^^^^^^^^^^^^^^^
  File "/home/ubuntu/airflow_environment/lib/python3.12/site-packages/pandas/core/generic.py", line 3967, in to_csv
    return DataFrameRenderer(formatter).to_csv(
           ^^^^^^^^^^^^^^^^^^^^^^^^^^^^^^^^^^^^
  File "/home/ubuntu/airflow_environment/lib/python3.12/site-packages/pandas/io/formats/format.py", line 1014, in to_csv
    csv_formatter.save()
  File "/home/ubuntu/airflow_environment/lib/python3.12/site-packages/pandas/io/formats/csvs.py", line 251, in save
    with get_handle(
         ^^^^^^^^^^^
  File "/home/ubuntu/airflow_environment/lib/python3.12/site-packages/pandas/io/common.py", line 728, in get_handle
    ioargs = _get_filepath_or_buffer(
             ^^^^^^^^^^^^^^^^^^^^^^^^
  File "/home/ubuntu/airflow_environment/lib/python3.12/site-packages/pandas/io/common.py", line 430, in _get_filepath_or_buffer
    file_obj = fsspec.open(
               ^^^^^^^^^^^^
  File "/home/ubuntu/airflow_environment/lib/python3.12/site-packages/fsspec/core.py", line 461, in open
    out = open_files(
          ^^^^^^^^^^^
  File "/home/ubuntu/airflow_environment/lib/python3.12/site-packages/fsspec/core.py", line 298, in open_files
    fs.makedirs(parent, exist_ok=True)
  File "/home/ubuntu/airflow_environment/lib/python3.12/site-packages/fsspec/asyn.py", line 118, in wrapper
    return sync(self.loop, func, *args, **kwargs)
           ^^^^^^^^^^^^^^^^^^^^^^^^^^^^^^^^^^^^^^
  File "/home/ubuntu/airflow_environment/lib/python3.12/site-packages/fsspec/asyn.py", line 103, in sync
    raise return_result
  File "/home/ubuntu/airflow_environment/lib/python3.12/site-packages/fsspec/asyn.py", line 56, in _runner
    result[0] = await coro
                ^^^^^^^^^^
  File "/home/ubuntu/airflow_environment/lib/python3.12/site-packages/s3fs/core.py", line 934, in _makedirs
    await self._mkdir(path, create_parents=True)
  File "/home/ubuntu/airflow_environment/lib/python3.12/site-packages/s3fs/core.py", line 919, in _mkdir
    await self._call_s3("create_bucket", **params)
  File "/home/ubuntu/airflow_environment/lib/python3.12/site-packages/s3fs/core.py", line 362, in _call_s3
    return await _error_wrapper(
           ^^^^^^^^^^^^^^^^^^^^^
  File "/home/ubuntu/airflow_environment/lib/python3.12/site-packages/s3fs/core.py", line 142, in _error_wrapper
    raise err
OSError: [Errno 22] The provided token is malformed or otherwise invalid.
[2024-05-04T07:23:37.592+0000] {taskinstance.py:1205} INFO - Marking task as FAILED. dag_id=weather_dag, task_id=transform_load_weather_data, execution_date=20240504T071916, start_date=20240504T072336, end_date=20240504T072337
[2024-05-04T07:23:37.604+0000] {standard_task_runner.py:110} ERROR - Failed to execute job 36 for task transform_load_weather_data ([Errno 22] The provided token is malformed or otherwise invalid.; 26130)
[2024-05-04T07:23:37.622+0000] {local_task_job_runner.py:240} INFO - Task exited with return code 1
[2024-05-04T07:23:37.634+0000] {taskinstance.py:3482} INFO - 0 downstream tasks scheduled from follow-on schedule check
[2024-05-04T07:23:37.634+0000] {local_task_job_runner.py:222} INFO - ::endgroup::
